Workbook

Sheet Consolidation_Summary
A1: Consolidated Version | B1: v8 lean / JD-fit
A2: Purpose | B2: Remove duplicate sheets and simplify Streamlit dashboard tabs while preserving content in core sheets.
A4: Removed Sheet | B4: Merged Into
A5: Meeting_Brief | B5: Meeting_Intelligence
A6: Regional_Report_Pack | B6: Executive_Brief
A7: Monthly_RO_Report_Generator | B7: Executive_Brief
A8: Relationship_Intelligence | B8: Regulator_CRM
A9: Risk_Radar | B9: Policy_Monitoring
A10: Regulatory_News_Feed | B10: Policy_Monitoring
A11: Interview_Story_Mode | B11: Interview_Demo_Mode
A12: Demo_Script_Mode | B12: Interview_Demo_Mode
A13: Version_Change_Log | B13: Removed
A14: Excel_Streamlit_Integration | B14: Removed from dashboard / concept retained in user guide

Sheet Executive_Dashboard
A1: Manulife Vietnam Regulatory & Public Affairs Command Center v4.0 (v3 fully inherited + v4 modules added)
A3: KPI | B3: Value | C3: Interpretation | D3: Formula / Source
A4: Reports due in 7 days | B4: =COUNTIF(Regulatory_Calendar!H2:H31,"Due Soon") | C4: Deadline pressure | D4: Regulatory_Calendar
A5: Overdue reports | B5: =COUNTIF(Regulatory_Calendar!H2:H31,"Overdue") | C5: Needs escalation | D5: Regulatory_Calendar
A6: Pending submissions | B6: =COUNTIFS(Submission_Tracker!I2:I61,"<>Submitted",Submission_Tracker!I2:I61,"<>Approved") | C6: Open workload | D6: Submission_Tracker
A7: Pending approvals | B7: =COUNTIFS(Approval_Pipeline!F2:F26,"<>Approved",Approval_Pipeline!F2:F26,"<>Rejected/Withdrawn") | C7: Regulatory pipeline | D7: Approval_Pipeline
A8: High policy risk items | B8: =COUNTIF(Policy_Monitoring!I2:I11,">=10") | C8: Early warning | D8: Policy_Monitoring
A9: Average relationship strength | B9: =ROUND(AVERAGE(Relationship_Intelligence!D2:D7),2) | C9: Regulator trust base | D9: Relationship_Intelligence
A10: Open follow-ups | B10: =COUNTIF(Regulator_Interactions!K2:K49,"Open") | C10: Action discipline | D10: Regulator_Interactions
A11: Translation overdue | B11: =COUNTIF(Translation_Tracker!G2:G21,"Overdue") | C11: Operational support | D11: Translation_Tracker
A13: Recommended Weekly Operating Rhythm
A14: Day | B14: Action | C14: Output | D14: Owner
A15: Monday | B15: Review deadline dashboard and overdue items | C15: Escalation list | D15: Public Affairs
A16: Tuesday | B16: Policy monitoring and regulator news scan | C16: Policy radar memo | D16: Public Affairs
A17: Wednesday | B17: Check submission quality and internal follow-up | C17: Submission status update | D17: Legal/Compliance/Business
A18: Thursday | B18: Prepare meeting briefs and regulator interaction notes | C18: Briefing pack | D18: Public Affairs
A19: Friday | B19: Regional Office reporting pack | C19: Weekly regulatory update | D19: Public Affairs
A21: How this model fits the JD: reporting documents, regulatory research, deadline reminders, official letter quality review, approvals support, regulator interactions, meeting logistics, translation tracker.
A23: v4 Add-on Modules | B23: Purpose | C23: Primary Output | D23: How Streamlit Uses It
A24: Regulator CRM | B24: Create institutional memory for MOF/ISA/IAV/MIC/SBV/VCA | C24: Regulator profile, open issues, relationship plan | D24: CRM tab + relationship drilldown
A25: Knowledge Base | B25: Store summaries of key laws/circulars and obligations | C25: Key obligations and affected departments | D25: Knowledge Base AI-lite tab
A26: Workflow Engine | B26: Standardize request-to-submission process | C26: Workflow stage, owner, SLA and bottlenecks | D26: Approval/Submission workflow tab
A27: Executive Brief Generator | B27: Generate 30-second daily/weekly regulatory brief | C27: CEO/EMT style brief | D27: Executive Brief tab
A28: Approval Time Analytics | B28: Analyze average regulator approval time | C28: Lead-time benchmarks and bottlenecks | D28: Approval Analytics tab
A29: Public Affairs Scorecard | B29: Translate PA operations into measurable KPIs | C29: On-time rate, relationship score, risk closure | D29: Scorecard tab
A30: Risk Radar | B30: Quantify regulatory probability x impact | C30: High-priority risk heatmap | D30: Risk Radar tab

Sheet Regulatory_Calendar
A1: Obligation ID | B1: Report / Obligation | C1: Regulator | D1: Frequency | E1: Owner Dept | F1: Due Date | G1: Days to Due | H1: Status | I1: Quality Check | J1: Escalation | K1: Notes
A2: CAL-001 | B2: Monthly solvency monitoring report | C2: ISA | D2: Monthly | E2: Product | F2: 46179 | G2: =F2-TODAY() | H2: Overdue | I2: In Progress | J2: Yes | K2: Sample data - replace with actual obligation
A3: CAL-002 | B3: Quarterly capital adequacy report | C3: MOF | D3: Quarterly | E3: Agency | F3: 46187 | G3: =F3-TODAY() | H3: Due Soon | I3: Not Started | J3: No | K3: Sample data - replace with actual obligation
A4: CAL-003 | B4: Annual audited financial statement filing | C4: MOF | D4: Annual | E4: Bancassurance | F4: 46184 | G4: =F4-TODAY() | H4: Due Soon | I4: Completed | J4: No | K4: Sample data - replace with actual obligation
A5: CAL-004 | B5: Product approval status update | C5: ISA | D5: Ad-hoc | E5: Operations | F5: 46179 | G5: =F5-TODAY() | H5: Submitted | I5: Completed | J5: No | K5: Sample data - replace with actual obligation
A6: CAL-005 | B6: Agency training approval report | C6: ISA | D6: Monthly | E6: CEO Office | F6: 46179 | G6: =F6-TODAY() | H6: Submitted | I6: Not Started | J6: No | K6: Sample data - replace with actual obligation
A7: CAL-006 | B7: Bancassurance compliance update | C7: SBV | D7: Quarterly | E7: Legal | F7: 46172 | G7: =F7-TODAY() | H7: Overdue | I7: Not Started | J7: Yes | K7: Sample data - replace with actual obligation
A8: CAL-007 | B8: Consumer complaint summary | C8: VCA | D8: Monthly | E8: Compliance | F8: 46219 | G8: =F8-TODAY() | H8: On Track | I8: Completed | J8: No | K8: Sample data - replace with actual obligation
A9: CAL-008 | B9: AML / CFT compliance certification | C9: MOF | D9: Annual | E9: Finance | F9: 46172 | G9: =F9-TODAY() | H9: Submitted | I9: Completed | J9: No | K9: Sample data - replace with actual obligation
A10: CAL-009 | B10: Data privacy compliance update | C10: MIC | D10: Quarterly | E10: Product | F10: 46219 | G10: =F10-TODAY() | H10: On Track | I10: In Progress | J10: No | K10: Sample data - replace with actual obligation
A11: CAL-010 | B11: Market conduct remediation update | C11: ISA | D11: Ad-hoc | E11: Agency | F11: 46187 | G11: =F11-TODAY() | H11: Due Soon | I11: In Progress | J11: No | K11: Sample data - replace with actual obligation
A12: CAL-011 | B12: Regional Office regulatory update | C12: Regional Office | D12: Monthly | E12: Bancassurance | F12: 46232 | G12: =F12-TODAY() | H12: On Track | I12: In Progress | J12: No | K12: Sample data - replace with actual obligation
A13: CAL-012 | B13: Ad-hoc ISA information request | C13: ISA | D13: Ad-hoc | E13: Operations | F13: 46172 | G13: =F13-TODAY() | H13: Submitted | I13: Not Started | J13: No | K13: Sample data - replace with actual obligation
... A31: CAL-030 | B31: Bancassurance compliance update | C31: SBV | D31: Quarterly | E31: Legal | F31: 46192 | G31: =F31-TODAY() | H31: On Track | I31: In Progress | J31: No | K31: Sample data - replace with actual obligation

Sheet Submission_Tracker
A1: Submission ID | B1: Document / Request | C1: Regulator | D1: Submission Type | E1: Owner Dept | F1: Received Date | G1: Submission Due Date | H1: Submitted Date | I1: Status | J1: Lead Time Days | K1: Checklist Complete | L1: Risk Level | M1: Next Action
A2: SUB-001 | B2: License/Transaction - item 1 | C2: MOF | D2: Agency Training | E2: Finance | F2: 46157 | G2: 46183 | I2: In Review | J2: =IF(H2="",TODAY()-F2,H2-F2) | K2: Partial | L2: Low | M2: Follow-up / quality review
A3: SUB-002 | B3: License/Transaction - item 2 | C3: SBV | D3: Report | E3: Bancassurance | F3: 46152 | G3: 46162 | H3: 46160 | I3: Submitted | J3: =IF(H3="",TODAY()-F3,H3-F3) | K3: Yes | L3: High | M3: Follow-up / quality review
A4: SUB-003 | B4: New Product Approval - item 3 | C4: MOF | D4: Report | E4: Bancassurance | F4: 46179 | G4: 46209 | I4: In Review | J4: =IF(H4="",TODAY()-F4,H4-F4) | K4: Yes | L4: Low | M4: Follow-up / quality review
A5: SUB-004 | B5: Report - item 4 | C5: IAV | D5: Report | E5: Product | F5: 46120 | G5: 46137 | H5: 46134 | I5: Approved | J5: =IF(H5="",TODAY()-F5,H5-F5) | K5: Partial | L5: Low | M5: Follow-up / quality review
A6: SUB-005 | B6: Agency Training - item 5 | C6: MIC | D6: New Product Approval | E6: Product | F6: 46115 | G6: 46128 | H6: 46125 | I6: Approved | J6: =IF(H6="",TODAY()-F6,H6-F6) | K6: Yes | L6: Low | M6: Follow-up / quality review
A7: SUB-006 | B7: Report - item 6 | C7: ISA | D7: Ad-hoc Response | E7: Operations | F7: 46120 | G7: 46127 | H7: 46127 | I7: Approved | J7: =IF(H7="",TODAY()-F7,H7-F7) | K7: Partial | L7: High | M7: Follow-up / quality review
A8: SUB-007 | B8: Agency Training - item 7 | C8: IAV | D8: Agency Training | E8: Legal | F8: 46134 | G8: 46151 | H8: 46148 | I8: Submitted | J8: =IF(H8="",TODAY()-F8,H8-F8) | K8: Partial | L8: Low | M8: Follow-up / quality review
A9: SUB-008 | B9: Ad-hoc Response - item 8 | C9: IAV | D9: Official Letter | E9: Agency | F9: 46169 | G9: 46195 | H9: 46193 | I9: Approved | J9: =IF(H9="",TODAY()-F9,H9-F9) | K9: No | L9: High | M9: Follow-up / quality review
A10: SUB-009 | B10: License/Transaction - item 9 | C10: IAV | D10: Agency Training | E10: Finance | F10: 46125 | G10: 46130 | I10: Overdue | J10: =IF(H10="",TODAY()-F10,H10-F10) | K10: Partial | L10: High | M10: Follow-up / quality review
A11: SUB-010 | B11: Report - item 10 | C11: IAV | D11: Ad-hoc Response | E11: Finance | F11: 46103 | G11: 46117 | H11: 46116 | I11: Approved | J11: =IF(H11="",TODAY()-F11,H11-F11) | K11: Partial | L11: Low | M11: Follow-up / quality review
A12: SUB-011 | B12: Official Letter - item 11 | C12: MOF | D12: New Product Approval | E12: Agency | F12: 46183 | G12: 46207 | I12: In Review | J12: =IF(H12="",TODAY()-F12,H12-F12) | K12: Yes | L12: High | M12: Follow-up / quality review
A13: SUB-012 | B13: Official Letter - item 12 | C13: MIC | D13: Ad-hoc Response | E13: Compliance | F13: 46153 | G13: 46176 | I13: Overdue | J13: =IF(H13="",TODAY()-F13,H13-F13) | K13: Partial | L13: High | M13: Follow-up / quality review
A14: SUB-013 | B14: New Product Approval - item 13 | C14: SBV | D14: Ad-hoc Response | E14: Operations | F14: 46167 | G14: 46193 | H14: 46192 | I14: Submitted | J14: =IF(H14="",TODAY()-F14,H14-F14) | K14: Yes | L14: Low | M14: Follow-up / quality review
A15: SUB-014 | B15: Capital Injection - item 14 | C15: IAV | D15: Capital Injection | E15: CEO Office | F15: 46087 | G15: 46115 | H15: 46113 | I15: Approved | J15: =IF(H15="",TODAY()-F15,H15-F15) | K15: Yes | L15: High | M15: Follow-up / quality review
A16: SUB-015 | B16: Agency Training - item 15 | C16: SBV | D16: Report | E16: Product | F16: 46155 | G16: 46162 | I16: In Review | J16: =IF(H16="",TODAY()-F16,H16-F16) | K16: Yes | L16: High | M16: Follow-up / quality review
A17: SUB-016 | B17: Official Letter - item 16 | C17: MOF | D17: Ad-hoc Response | E17: Bancassurance | F17: 46093 | G17: 46118 | I17: Drafting | J17: =IF(H17="",TODAY()-F17,H17-F17) | K17: Yes | L17: Low | M17: Follow-up / quality review
A18: SUB-017 | B18: Agency Training - item 17 | C18: ISA | D18: License/Transaction | E18: CEO Office | F18: 46153 | G18: 46166 | H18: 46165 | I18: Approved | J18: =IF(H18="",TODAY()-F18,H18-F18) | K18: Yes | L18: Medium | M18: Follow-up / quality review
A19: SUB-018 | B19: License/Transaction - item 18 | C19: MIC | D19: New Product Approval | E19: Operations | F19: 46131 | G19: 46142 | I19: Drafting | J19: =IF(H19="",TODAY()-F19,H19-F19) | K19: No | L19: Medium | M19: Follow-up / quality review
A20: SUB-019 | B20: Official Letter - item 19 | C20: MIC | D20: License/Transaction | E20: Bancassurance | F20: 46090 | G20: 46096 | H20: 46096 | I20: Approved | J20: =IF(H20="",TODAY()-F20,H20-F20) | K20: Yes | L20: High | M20: Follow-up / quality review
A21: SUB-020 | B21: Capital Injection - item 20 | C21: ISA | D21: New Product Approval | E21: CEO Office | F21: 46159 | G21: 46170 | H21: 46169 | I21: Submitted | J21: =IF(H21="",TODAY()-F21,H21-F21) | K21: Yes | L21: High | M21: Follow-up / quality review
A22: SUB-021 | B22: Official Letter - item 21 | C22: SBV | D22: Ad-hoc Response | E22: Legal | F22: 46127 | G22: 46157 | H22: 46157 | I22: Approved | J22: =IF(H22="",TODAY()-F22,H22-F22) | K22: Yes | L22: High | M22: Follow-up / quality review
A23: SUB-022 | B23: Ad-hoc Response - item 22 | C23: MIC | D23: Official Letter | E23: Finance | F23: 46162 | G23: 46180 | H23: 46179 | I23: Submitted | J23: =IF(H23="",TODAY()-F23,H23-F23) | K23: No | L23: High | M23: Follow-up / quality review
A24: SUB-023 | B24: Ad-hoc Response - item 23 | C24: MIC | D24: New Product Approval | E24: Operations | F24: 46134 | G24: 46147 | I24: Overdue | J24: =IF(H24="",TODAY()-F24,H24-F24) | K24: Partial | L24: Low | M24: Follow-up / quality review
A25: SUB-024 | B25: Report - item 24 | C25: IAV | D25: Report | E25: Legal | F25: 46112 | G25: 46138 | H25: 46137 | I25: Approved | J25: =IF(H25="",TODAY()-F25,H25-F25) | K25: Partial | L25: Low | M25: Follow-up / quality review
A26: SUB-025 | B26: Official Letter - item 25 | C26: SBV | D26: Capital Injection | E26: Finance | F26: 46114 | G26: 46120 | H26: 46120 | I26: Approved | J26: =IF(H26="",TODAY()-F26,H26-F26) | K26: Yes | L26: Low | M26: Follow-up / quality review
A27: SUB-026 | B27: Official Letter - item 26 | C27: ISA | D27: Capital Injection | E27: Compliance | F27: 46173 | G27: 46183 | I27: Drafting | J27: =IF(H27="",TODAY()-F27,H27-F27) | K27: Partial | L27: High | M27: Follow-up / quality review
A28: SUB-027 | B28: Official Letter - item 27 | C28: MIC | D28: License/Transaction | E28: Bancassurance | F28: 46109 | G28: 46133 | I28: Drafting | J28: =IF(H28="",TODAY()-F28,H28-F28) | K28: No | L28: High | M28: Follow-up / quality review
A29: SUB-028 | B29: New Product Approval - item 28 | C29: MIC | D29: Report | E29: Agency | F29: 46098 | G29: 46125 | I29: In Review | J29: =IF(H29="",TODAY()-F29,H29-F29) | K29: No | L29: Medium | M29: Follow-up / quality review
A30: SUB-029 | B30: Agency Training - item 29 | C30: SBV | D30: Official Letter | E30: Compliance | F30: 46087 | G30: 46094 | I30: Drafting | J30: =IF(H30="",TODAY()-F30,H30-F30) | K30: Partial | L30: High | M30: Follow-up / quality review
A31: SUB-030 | B31: New Product Approval - item 30 | C31: MOF | D31: Report | E31: Bancassurance | F31: 46119 | G31: 46132 | I31: Waiting Internal Input | J31: =IF(H31="",TODAY()-F31,H31-F31) | K31: No | L31: High | M31: Follow-up / quality review
A32: SUB-031 | B32: License/Transaction - item 31 | C32: SBV | D32: New Product Approval | E32: Compliance | F32: 46127 | G32: 46149 | H32: 46149 | I32: Approved | J32: =IF(H32="",TODAY()-F32,H32-F32) | K32: Yes | L32: Medium | M32: Follow-up / quality review
A33: SUB-032 | B33: New Product Approval - item 32 | C33: IAV | D33: Agency Training | E33: Product | F33: 46169 | G33: 46177 | H33: 46176 | I33: Approved | J33: =IF(H33="",TODAY()-F33,H33-F33) | K33: Partial | L33: Medium | M33: Follow-up / quality review
A34: SUB-033 | B34: Agency Training - item 33 | C34: MIC | D34: New Product Approval | E34: Legal | F34: 46157 | G34: 46183 | H34: 46181 | I34: Submitted | J34: =IF(H34="",TODAY()-F34,H34-F34) | K34: Yes | L34: Low | M34: Follow-up / quality review
A35: SUB-034 | B35: New Product Approval - item 34 | C35: ISA | D35: License/Transaction | E35: Agency | F35: 46129 | G35: 46142 | I35: Drafting | J35: =IF(H35="",TODAY()-F35,H35-F35) | K35: Yes | L35: Low | M35: Follow-up / quality review
A36: SUB-035 | B36: Official Letter - item 35 | C36: MOF | D36: License/Transaction | E36: Finance | F36: 46127 | G36: 46149 | H36: 46149 | I36: Approved | J36: =IF(H36="",TODAY()-F36,H36-F36) | K36: Partial | L36: High | M36: Follow-up / quality review
A37: SUB-036 | B37: Report - item 36 | C37: MOF | D37: New Product Approval | E37: Bancassurance | F37: 46136 | G37: 46159 | H37: 46156 | I37: Submitted | J37: =IF(H37="",TODAY()-F37,H37-F37) | K37: Yes | L37: Medium | M37: Follow-up / quality review
A38: SUB-037 | B38: Official Letter - item 37 | C38: IAV | D38: Ad-hoc Response | E38: Operations | F38: 46157 | G38: 46183 | I38: In Review | J38: =IF(H38="",TODAY()-F38,H38-F38) | K38: Partial | L38: Low | M38: Follow-up / quality review
A39: SUB-038 | B39: Capital Injection - item 38 | C39: MOF | D39: Report | E39: Bancassurance | F39: 46164 | G39: 46176 | H39: 46175 | I39: Approved | J39: =IF(H39="",TODAY()-F39,H39-F39) | K39: No | L39: Low | M39: Follow-up / quality review
A40: SUB-039 | B40: Report - item 39 | C40: MOF | D40: Capital Injection | E40: Legal | F40: 46089 | G40: 46119 | I40: In Review | J40: =IF(H40="",TODAY()-F40,H40-F40) | K40: No | L40: High | M40: Follow-up / quality review
...

Sheet Approval_Pipeline
A1: Approval ID | B1: Approval Item | C1: Category | D1: Regulator | E1: Business Owner | F1: Current Stage | G1: Request Date | H1: Target Approval Date | I1: Days in Pipeline | J1: Probability of Approval (%) | K1: Business Impact | L1: Blocker | M1: Next Action
A2: APR-001 | B2: Health Rider Update 1 | C2: License | D2: MOF | E2: Agency | F2: Approved | G2: 46111 | H2: 46200 | I2: =TODAY()-G2 | J2: 72 | K2: Medium | L2: None | M2: Prepare response / follow up
A3: APR-002 | B3: Agency Training Program 2 | C3: Distribution | D3: MOF | E3: Bancassurance | F3: Regulator Q&A | G3: 46130 | H3: 46193 | I3: =TODAY()-G3 | J3: 53 | K3: Low | L3: Internal sign-off | M3: Prepare response / follow up
A4: APR-003 | B4: License Amendment 3 | C4: Product | D4: MOF | E4: Bancassurance | F4: Regulator Q&A | G4: 46176 | H4: 46246 | I4: =TODAY()-G4 | J4: 53 | K4: Medium | L4: Awaiting legal memo | M4: Prepare response / follow up
A5: APR-004 | B5: Health Rider Update 4 | C5: License | D5: ISA | E5: Agency | F5: Submitted to Regulator | G5: 46173 | H5: 46226 | I5: =TODAY()-G5 | J5: 93 | K5: Medium | L5: Missing attachment | M5: Prepare response / follow up
A6: APR-005 | B6: New UL Product 5 | C6: License | D6: MOF | E6: CEO Office | F6: Compliance Review | G6: 46083 | H6: 46156 | I6: =TODAY()-G6 | J6: 48 | K6: Medium | L6: Awaiting legal memo | M6: Prepare response / follow up
A7: APR-006 | B7: License Amendment 6 | C7: Product | D7: MOF | E7: Finance | F7: Approved | G7: 46096 | H7: 46124 | I7: =TODAY()-G7 | J7: 57 | K7: High | L7: Internal sign-off | M7: Prepare response / follow up
A8: APR-007 | B8: License Amendment 7 | C8: Product | D8: MOF | E8: Bancassurance | F8: Legal Review | G8: 46160 | H8: 46210 | I8: =TODAY()-G8 | J8: 89 | K8: Medium | L8: Missing attachment | M8: Prepare response / follow up
A9: APR-008 | B9: Health Rider Update 8 | C9: Agency | D9: MOF | E9: CEO Office | F9: Approved | G9: 46158 | H9: 46192 | I9: =TODAY()-G9 | J9: 46 | K9: Medium | L9: Internal sign-off | M9: Prepare response / follow up
A10: APR-009 | B10: License Amendment 9 | C10: Capital | D10: MOF | E10: CEO Office | F10: Submitted to Regulator | G10: 46093 | H10: 46161 | I10: =TODAY()-G10 | J10: 89 | K10: Low | L10: Awaiting legal memo | M10: Prepare response / follow up
A11: APR-010 | B11: Bancassurance Campaign 10 | C11: Product | D11: MOF | E11: Agency | F11: Approved | G11: 46166 | H11: 46224 | I11: =TODAY()-G11 | J11: 79 | K11: Medium | L11: Missing attachment | M11: Prepare response / follow up
A12: APR-011 | B12: New UL Product 11 | C12: License | D12: ISA | E12: Product | F12: Regulator Q&A | G12: 46171 | H12: 46255 | I12: =TODAY()-G12 | J12: 72 | K12: Medium | L12: Regulator Q&A | M12: Prepare response / follow up
A13: APR-012 | B13: License Amendment 12 | C13: Transaction | D13: ISA | E13: CEO Office | F13: Submitted to Regulator | G13: 46089 | H13: 46128 | I13: =TODAY()-G13 | J13: 79 | K13: Medium | L13: Regulator Q&A | M13: Prepare response / follow up
... A26: APR-025 | B26: Agency Training Program 25 | C26: License | D26: ISA | E26: Agency | F26: Approved | G26: 46103 | H26: 46151 | I26: =TODAY()-G26 | J26: 82 | K26: Medium | L26: Missing attachment | M26: Prepare response / follow up

Sheet Regulator_Interactions
A1: Interaction ID | B1: Date | C1: Regulator | D1: Person / Unit | E1: Topic | F1: Interaction Type | G1: Tone | H1: Key Message | I1: Follow-up Owner | J1: Follow-up Due | K1: Status
A2: INT-001 | B2: 45601 | C2: MIC | D2: Policy Dept | E2: Capital requirement | F2: Call | G2: Neutral | H2: Provide transparent update and confirm next steps | I2: Agency | J2: 45606 | K2: Open
A3: INT-002 | B3: 45938 | C3: ISA | D3: Association Secretariat | E3: Capital requirement | F3: Call | G3: Positive | H3: Provide transparent update and confirm next steps | I3: Operations | J3: 45955 | K3: In Progress
A4: INT-003 | B4: 45575 | C4: SBV | D4: Insurance Supervision Team | E4: Product approval | F4: Call | G4: Cautious | H4: Provide transparent update and confirm next steps | I4: Agency | J4: 45592 | K4: Open
A5: INT-004 | B5: 45480 | C5: ISA | D5: Insurance Supervision Team | E5: Consumer complaints | F5: Submission counter | G5: Positive | H5: Provide transparent update and confirm next steps | I5: Product | J5: 45487 | K5: Closed
A6: INT-005 | B6: 46038 | C6: MOF | D6: Policy Dept | E6: Market conduct | F6: Email | G6: Cautious | H6: Provide transparent update and confirm next steps | I6: CEO Office | J6: 46044 | K6: Closed
A7: INT-006 | B7: 45478 | C7: IAV | D7: Legal Unit | E7: Data privacy | F7: Workshop | G7: Concerned | H7: Provide transparent update and confirm next steps | I7: CEO Office | J7: 45483 | K7: In Progress
A8: INT-007 | B8: 46143 | C8: SBV | D8: Insurance Supervision Team | E8: Data privacy | F8: Meeting | G8: Positive | H8: Provide transparent update and confirm next steps | I8: Product | J8: 46146 | K8: In Progress
A9: INT-008 | B9: 45908 | C9: MIC | D9: Policy Dept | E9: Market conduct | F9: Submission counter | G9: Concerned | H9: Provide transparent update and confirm next steps | I9: Agency | J9: 45916 | K9: In Progress
A10: INT-009 | B10: 45737 | C10: VCA | D10: Legal Unit | E10: Capital requirement | F10: Submission counter | G10: Cautious | H10: Provide transparent update and confirm next steps | I10: Operations | J10: 45750 | K10: Closed
A11: INT-010 | B11: 45497 | C11: MOF | D11: Administrative Office | E11: Bancassurance | F11: Submission counter | G11: Concerned | H11: Provide transparent update and confirm next steps | I11: Agency | J11: 45512 | K11: In Progress
A12: INT-011 | B12: 46146 | C12: SBV | D12: Policy Dept | E12: Bancassurance | F12: Email | G12: Cautious | H12: Provide transparent update and confirm next steps | I12: Compliance | J12: 46161 | K12: In Progress
A13: INT-012 | B13: 46182 | C13: VCA | D13: Association Secretariat | E13: ESG reporting | F13: Submission counter | G13: Positive | H13: Provide transparent update and confirm next steps | I13: Product | J13: 46201 | K13: Closed
... A49: INT-048 | B49: 46157 | C49: ISA | D49: Policy Dept | E49: Bancassurance | F49: Call | G49: Cautious | H49: Provide transparent update and confirm next steps | I49: Legal | J49: 46165 | K49: Closed

Sheet Policy_Monitoring
A1: Policy ID | B1: Policy / Regulation | C1: Agency | D1: Policy Stage | E1: Expected Timeline | F1: Probability (%) | G1: Business Impact (1-5) | H1: Reputation Impact (1-5) | I1: Risk Score | J1: Opportunity | K1: Recommended Action | L1: Owner
A2: POL-001 | B2: Insurance Law amendment | C2: MOF | D2: Draft discussion | E2: 0-3 months | F2: 38 | G2: 3 | H2: 4 | I2: =ROUND(F2*G2*H2/100,2) | J2: High | K2: Monitor, prepare internal memo and engage via association | L2: Legal
A3: POL-002 | B3: Circular on product approval process | C3: ISA | D3: Consultation | E3: 0-3 months | F3: 65 | G3: 5 | H3: 3 | I3: =ROUND(F3*G3*H3/100,2) | J3: Medium | K3: Monitor, prepare internal memo and engage via association | L3: Compliance
A4: POL-003 | B4: Bancassurance conduct guideline | C4: SBV / MOF | D4: Drafting | E4: 6-12 months | F4: 74 | G4: 2 | H4: 5 | I4: =ROUND(F4*G4*H4/100,2) | J4: Medium | K4: Monitor, prepare internal memo and engage via association | L4: Legal
A5: POL-004 | B5: Personal data protection implementation | C5: MIC | D5: Implementation | E5: 12+ months | F5: 38 | G5: 5 | H5: 4 | I5: =ROUND(F5*G5*H5/100,2) | J5: High | K5: Monitor, prepare internal memo and engage via association | L5: Legal
A6: POL-005 | B6: Consumer protection reporting requirement | C6: VCA | D6: Effective soon | E6: 0-3 months | F6: 66 | G6: 5 | H6: 1 | I6: =ROUND(F6*G6*H6/100,2) | J6: Medium | K6: Monitor, prepare internal memo and engage via association | L6: Compliance
A7: POL-006 | B7: Mandatory ESG disclosure for insurers | C7: MOF | D7: Early consultation | E7: 6-12 months | F7: 39 | G7: 3 | H7: 3 | I7: =ROUND(F7*G7*H7/100,2) | J7: Medium | K7: Monitor, prepare internal memo and engage via association | L7: Public Affairs
A8: POL-007 | B8: Capital adequacy and solvency update | C8: ISA | D8: Consultation | E8: 0-3 months | F8: 64 | G8: 5 | H8: 1 | I8: =ROUND(F8*G8*H8/100,2) | J8: High | K8: Monitor, prepare internal memo and engage via association | L8: Compliance
A9: POL-008 | B9: Agency training standard revision | C9: ISA | D9: Drafting | E9: 12+ months | F9: 62 | G9: 5 | H9: 2 | I9: =ROUND(F9*G9*H9/100,2) | J9: Medium | K9: Monitor, prepare internal memo and engage via association | L9: Risk
A10: POL-009 | B10: Digital insurance distribution rules | C10: MIC / MOF | D10: Policy design | E10: 6-12 months | F10: 60 | G10: 5 | H10: 1 | I10: =ROUND(F10*G10*H10/100,2) | J10: Medium | K10: Monitor, prepare internal memo and engage via association | L10: Public Affairs
A11: POL-010 | B11: Complaint handling transparency requirement | C11: VCA / ISA | D11: Drafting | E11: 3-6 months | F11: 77 | G11: 4 | H11: 3 | I11: =ROUND(F11*G11*H11/100,2) | J11: High | K11: Monitor, prepare internal memo and engage via association | L11: Risk
A13: Consolidation Note | B13: Risk_Radar and Regulatory_News_Feed consolidated here. Use Policy_Monitoring as the single source for policy signals, probability, impact and recommended actions.
A15: Consolidated Risk Radar Items
A16: Risk ID | B16: Regulatory Topic | C16: Agency | D16: Probability (1-5) | E16: Impact (1-5) | F16: Preparedness (1-5) | G16: Risk Score | H16: Risk Level | I16: Early Warning Signal | J16: Recommended Action | K16: Owner
A17: RR-001 | B17: Capital adequacy and solvency update | C17: ISA | D17: 4 | E17: 5 | F17: 3 | G17: =D4*E4/F4 | H17: High | I17: Draft circular discussion and industry consultation | J17: Prepare capital impact note and engage via IAV | K17: Finance + PA
A18: RR-002 | B18: Product approval process tightening | C18: ISA | D18: 5 | E18: 5 | F18: 3 | G18: =D5*E5/F5 | H18: High | I18: More detailed Q&A requests from regulator | J18: Create product dossier checklist and Q&A evidence bank | K18: Product + PA
A19: RR-003 | B19: Bancassurance conduct guideline | C19: SBV / MOF | D19: 4 | E19: 5 | F19: 3 | G19: =D6*E6/F6 | H19: High | I19: Banking sector conduct review and consumer complaints | J19: Develop customer-protection narrative and sales governance evidence | K19: Bancassurance + Compliance
A20: RR-004 | B20: Data localization and privacy enforcement | C20: MIC | D20: 4 | E20: 4 | F20: 2 | G20: =D7*E7/F7 | H20: High | I20: New data consultation and privacy inspections | J20: Prepare data-flow map and compliance briefing | K20: Digital + Legal
A21: RR-005 | B21: Consumer complaint transparency requirement | C21: VCA / ISA | D21: 3 | E21: 4 | F21: 3 | G21: =D8*E8/F8 | H21: Medium | I21: Increased complaint reporting and media attention | J21: Prepare complaint KPI pack and remediation narrative | K21: Compliance
A22: RR-006 | B22: Mandatory ESG disclosure | C22: MOF | D22: 3 | E22: 2 | F22: 3 | G22: =D9*E9/F9 | H22: Low | I22: Green finance roadmap and peer disclosure practices | J22: Create baseline ESG disclosure template | K22: Finance + PA
A24: Consolidated Regulatory News / Signal Items
A25: Signal ID | B25: Date | C25: Source / Agency | D25: Headline / Signal | E25: Category | F25: Auto Tag | G25: Relevance to Manulife | H25: Probability (1-5) | I25: Impact (1-5) | J25: Signal Score | K25: Suggested Action | L25: Owner | M25: Status
A26: NEWS-001 | B26: 46177 | C26: MOF | D26: Draft discussion on capital adequacy strengthening | E26: Capital | F26: Capital | G26: Potential increase in capital planning and reporting pressure | H26: 4 | I26: 5 | J26: =H5*I5 | K26: Prepare capital impact note and Finance briefing | L26: Finance / PA | M26: Monitoring
A27: NEWS-002 | B27: 46178 | C27: ISA | D27: Market conduct inspection activity increases across insurers | E27: Consumer Protection | F27: Market Conduct | G27: Higher scrutiny on complaints, sales conduct and product disclosure | H27: 5 | I27: 4 | J27: =H6*I6 | K27: Review complaint report and sales training evidence | L27: Compliance / PA | M27: Action Required
A28: NEWS-003 | B28: 46179 | C28: IAV | D28: Working group formed on standardized product disclosure | E28: Product Approval | F28: Product | G28: Opportunity to shape industry position on disclosure standards | H28: 3 | I28: 4 | J28: =H7*I7 | K28: Join working group and draft Manulife input | L28: Product / PA | M28: Open
A29: NEWS-004 | B29: 46180 | C29: MIC | D29: Consultation on data localization implementation guidance | E29: Data Privacy | F29: Data | G29: Potential impact on digital insurance and regional data processing | H29: 4 | I29: 4 | J29: =H8*I8 | K29: Prepare data-flow map and legal position | L29: IT / Legal | M29: Monitoring
A30: NEWS-005 | B30: 46181 | C30: SBV | D30: Review of bancassurance sales practice risk | E30: Distribution | F30: Bancassurance | G30: Potential change to bank channel monitoring requirements | H30: 4 | I30: 5 | J30: =H9*I9 | K30: Coordinate with bank partners and Compliance | L30: Distribution | M30: Action Required
A31: NEWS-006 | B31: 46183 | C31: Regional Office | D31: APAC request for ESG disclosure readiness update | E31: ESG | F31: ESG | G31: Need consistent local-to-regional ESG reporting pack | H31: 3 | I31: 3 | J31: =H10*I10 | K31: Prepare ESG readiness note | L31: Strategy / PA | M31: Open

Sheet Translation_Tracker
A1: Document ID | B1: Document Name | C1: Direction | D1: Owner | E1: Received Date | F1: Due Date | G1: Status | H1: SLA Days | I1: Notes
A2: TR-001 | B2: Circular summary 1 | C2: VN -> EN | D2: Legal | E2: 46182 | F2: 46183 | G2: Not Started | H2: =F2-E2 | I2: Sample
A3: TR-002 | B3: Official letter 2 | C3: VN -> EN | D3: Compliance | E3: 46173 | F3: 46180 | G3: Done | H3: =F3-E3 | I3: Sample
A4: TR-003 | B4: Meeting note 3 | C4: EN -> VN | D4: Compliance | E4: 46181 | F4: 46185 | G4: Not Started | H4: =F4-E4 | I4: Sample
A5: TR-004 | B5: Meeting note 4 | C5: EN -> VN | D5: Public Affairs | E5: 46175 | F5: 46180 | G5: In Progress | H5: =F5-E5 | I5: Sample
A6: TR-005 | B6: Regional report 5 | C6: VN -> EN | D6: Public Affairs | E6: 46180 | F6: 46186 | G6: Done | H6: =F6-E6 | I6: Sample
A7: TR-006 | B7: Circular summary 6 | C7: EN -> VN | D7: Compliance | E7: 46167 | F7: 46170 | G7: In Progress | H7: =F7-E7 | I7: Sample
A8: TR-007 | B8: Product dossier 7 | C8: VN -> EN | D8: Compliance | E8: 46171 | F8: 46178 | G8: Done | H8: =F8-E8 | I8: Sample
A9: TR-008 | B9: Meeting note 8 | C9: EN -> VN | D9: Legal | E9: 46184 | F9: 46186 | G9: Done | H9: =F9-E9 | I9: Sample
A10: TR-009 | B10: Official letter 9 | C10: EN -> VN | D10: Public Affairs | E10: 46184 | F10: 46186 | G10: In Progress | H10: =F10-E10 | I10: Sample
A11: TR-010 | B11: Circular summary 10 | C11: VN -> EN | D11: Legal | E11: 46164 | F11: 46165 | G11: Overdue | H11: =F11-E11 | I11: Sample
A12: TR-011 | B12: Official letter 11 | C12: EN -> VN | D12: Legal | E12: 46170 | F12: 46173 | G12: Done | H12: =F12-E12 | I12: Sample
A13: TR-012 | B13: Circular summary 12 | C13: VN -> EN | D13: Public Affairs | E13: 46166 | F13: 46171 | G13: In Progress | H13: =F13-E13 | I13: Sample
... A21: TR-020 | B21: Official letter 20 | C21: EN -> VN | D21: Public Affairs | E21: 46172 | F21: 46177 | G21: Overdue | H21: =F21-E21 | I21: Sample

Sheet Reference_Lists
A1: Status | B1: Priority | C1: Risk Level | D1: Document Type | E1: Direction | F1: Escalation Level
A2: On Track | B2: Critical | C2: Critical | D2: Report | E2: Incoming | F2: Level 0
A3: Due Soon | B3: High | C3: High | D3: Official Letter | E3: Outgoing | F3: Level 1
A4: Overdue | B4: Medium | C4: Medium | D4: Product Dossier | E4: Internal | F4: Level 2
A5: Submitted | B5: Low | C5: Low | D5: Approval Request | E5: RO Reporting | F5: Level 3
A6: Approved | D6: Meeting Brief
A7: In Review | D7: Translation
A8: Drafting | D8: Regulator Response
A9: Waiting Internal Input | D9: Regional Office Report
A10: Open | D10: Other
A11: Closed
A12: In Progress
A14: Priority
A15: Critical
A16: High
A17: Medium
A18: Low
A20: Regulators
A21: MOF
A22: ISA
A23: IAV
A24: SBV
... A39: Risk

Sheet Daily_Control_Tower
A1: Daily Work Control Tower - Manulife VN Regulatory & Public Affairs
A3: KPI | B3: Formula / Source | C3: Value | D3: Interpretation
A4: Reports due this week | B4: Regulatory calendar due within 7 days | C4: =COUNTIFS(Regulatory_Calendar!F:F,">="&TODAY(),Regulatory_Calendar!F:F,"<="&TODAY()+7) | D4: Short-term workload
A5: Overdue regulatory items | B5: Calendar + submissions overdue | C5: =COUNTIF(Regulatory_Calendar!H:H,"Overdue")+COUNTIF(Submission_Tracker!I:I,"Overdue") | D5: Immediate escalation
A6: Pending MOF / ISA submissions | B6: Not yet submitted to MOF or ISA | C6: =COUNTIFS(Submission_Tracker!C:C,"MOF",Submission_Tracker!I:I,"<>Submitted")+COUNTIFS(Submission_Tracker!C:C,"ISA",Submission_Tracker!I:I,"<>Submitted") | D6: Key regulator workload
A7: Open regulator follow-ups | B7: Regulator interaction status open | C7: =COUNTIF(Regulator_Interactions!K:K,"Open")+COUNTIF(Regulator_Interactions!K:K,"In Progress") | D7: Relationship management
A8: Upcoming regulator meetings | B8: Interactions / follow-ups in next 14 days | C8: =COUNTIFS(Regulator_Interactions!J:J,">="&TODAY(),Regulator_Interactions!J:J,"<="&TODAY()+14) | D8: Preparation needs
A9: Documents pending QC | B9: Document checklist not approved | C9: =COUNTIF(Document_QC_Checklist!L:L,"Not Ready")+COUNTIF(Document_QC_Checklist!L:L,"Needs Review") | D9: Pre-submission control
A11: Priority Action List | B11: Source | C11: Item | D11: Regulator | E11: Owner | F11: Due Date | G11: Days Left | H11: Status | I11: Risk | J11: Required Action | K11: Escalation | L11: Notes
A12: Calendar | B12: Calendar | C12: Monthly solvency monitoring report | D12: ISA | E12: Product | F12: 46185 | G12: 1 | H12: Due Soon | I12: High | J12: Confirm source data and QA before submission | K12: No | L12: Prepare CEO Office note if delayed
A13: Submission | B13: Submission | C13: New product approval dossier | D13: MOF | E13: Legal | F13: 46187 | G13: 3 | H13: In Review | I13: Medium | J13: Complete official letter checklist and attachments | K13: No | L13: Coordinate with Compliance
A14: Meeting | B14: Meeting | C14: ISA technical working session | D14: ISA | E14: Public Affairs | F14: 46189 | G14: 5 | H14: Planned | I14: High | J14: Generate briefing note and talking points | K14: No | L14: Use meeting brief generator
A15: Translation | B15: Translation | C15: Circular summary VN to EN | D15: Regional Office | E15: Public Affairs | F15: 46186 | G15: 2 | H15: In Progress | I15: Medium | J15: Finalize English version for regional pack | K15: No | L15: Prioritize before weekly report
A16: QC | B16: QC | C16: Official letter to MOF | D16: MOF | E16: Regulatory Affairs | F16: 46184 | G16: 0 | H16: Needs Review | I16: High | J16: Verify signature authority and legal review | K16: Yes | L16: Escalate before 3pm
A18: How to use this tab
A19: This tab is designed as the default daily operating screen for the role. It converts the JD into a control tower: deadlines, regulator submissions, internal follow-ups, meeting preparation and document quality control. Review it every morning; update item owners and status during the day; escalate red items before end of day.

Sheet Document_QC_Checklist
A1: Document Quality Checklist - Official Letters / Reports / Dossiers
A3: Document ID | B3: Document Name | C3: Regulator | D3: Document Type | E3: Owner | F3: Due Date | G3: Correct Template | H3: Reference No. | I3: Signature Authority | J3: Legal Review | K3: Compliance Review | L3: Readiness Status | N3: QC Summary | O3: Formula | P3: Value | Q3: Comment
A4: DOC-001 | B4: Official letter re product approval | C4: MOF | D4: Official Letter | E4: Public Affairs | F4: 46187 | G4: Yes | H4: Yes | I4: Yes | J4: Yes | K4: Yes | L4: Ready | N4: Ready documents | O4: =COUNTIF(L:L,"Ready") | Q4: Can be submitted after final management approval
A5: DOC-002 | B5: Monthly solvency monitoring report | C5: ISA | D5: Regulatory Report | E5: Product | F5: 46185 | G5: Yes | H5: Yes | I5: Yes | J5: In Progress | K5: Yes | L5: Needs Review | N5: Needs review | O5: =COUNTIF(L:L,"Needs Review") | Q5: Follow up with Legal/Compliance/Owner
A6: DOC-003 | B6: Agency training approval dossier | C6: ISA | D6: Approval Dossier | E6: Agency | F6: 46191 | G6: Yes | H6: No | I6: Yes | J6: No | K6: In Progress | L6: Not Ready | N6: Not ready | O6: =COUNTIF(L:L,"Not Ready") | Q6: Escalate if due within 7 days
A7: DOC-004 | B7: Data privacy compliance update | C7: MIC | D7: Regulatory Report | E7: Compliance | F7: 46198 | G7: Yes | H7: Yes | I7: Yes | J7: Yes | K7: In Progress | L7: Needs Review
A8: DOC-005 | B8: Regional Office weekly regulatory pack | C8: Regional Office | D8: Management Report | E8: Public Affairs | F8: 46186 | G8: Yes | H8: N/A | I8: N/A | J8: N/A | K8: Yes | L8: Ready
A9: DOC-006 | B9: Capital increase supporting paper | C9: MOF | D9: Approval Dossier | E9: Finance | F9: 46194 | G9: Yes | H9: Yes | I9: Pending | J9: In Progress | K9: No | L9: Not Ready

Sheet Interview_Demo_Mode
A1: Interview Demo Mode - How to Present This Tool to Manulife
A3: Section | B3: Suggested Talking Points
A4: 1. Problem this tool solves | B4: The role requires accurate regulatory reporting, deadline control, document quality, regulator coordination and Regional Office reporting. This tool turns those responsibilities into a daily operating system.
A5: 2. Workflow | B5: Daily Control Tower → Regulatory Calendar → Submission Tracker → Document QC Checklist → Regulator Interaction Log → Meeting Brief → Regional Report Pack.
A6: 3. Example case | B6: If MOF requests an updated product approval dossier, I can track the request, assign owners, verify legal/compliance review, generate a meeting brief and include the issue in the Regional Office weekly pack.
A7: 4. Why Excel first | B7: Excel is practical, easy to audit and easy to share with Legal, Compliance, Product and Finance teams.
A8: 5. Why Streamlit next | B8: Streamlit adds automation, dashboarding, filtering, meeting brief generation and a more professional management view.
A9: 6. Business value | B9: Fewer missed deadlines, faster preparation for regulator meetings, stronger document control and clearer visibility for management.
A10: 7. Interview closing message | B10: My aim is not to build a complex system, but to create operational discipline for Regulatory & Public Affairs work from day one.
A13: Demo Script - 90 Seconds
A14: In this role, I understand that the core work is not only public affairs strategy, but day-to-day regulatory operations: tracking deadlines, reviewing official letters, coordinating with Legal and Compliance, submitting dossiers to MOF/ISA and preparing Regional Office updates. I built this model to demonstrate how I would organize the work. The Daily Control Tower shows urgent items. The Regulatory Calendar and Submission Tracker control deadlines. The Document QC Checklist reduces errors before documents go to regulators. The Meeting Brief Generator helps prepare CEO/EMT meetings with regulators. Over time, the same structure can be upgraded from Excel into Streamlit for automation and reporting.
A24: Consolidation Note | B24: Interview_Story_Mode and Demo_Script_Mode consolidated into Interview_Demo_Mode. Use one interview narrative only.

Sheet Regulator_CRM
A1: Regulator CRM / Institutional Memory
A3: Regulator | B3: Mandate / Role | C3: Key Units / Contact Point | D3: Relationship Strength (1-5) | E3: Sentiment | F3: Open Issues | G3: Pending Requests | H3: Next Engagement | I3: Engagement Owner | J3: Institutional Memory Note | K3: Power (1-5) | L3: Interest (1-5) | M3: Engagement Priority | N3: Key Concerns | O3: Relationship Risk Score
A4: MOF | B4: Insurance policy, capital and sector oversight | C4: Insurance policy department / administrative office | D4: 4 | E4: Positive | F4: Capital adequacy update; product approval process | G4: Quarterly capital note and market stability briefing | H4: Strategic dialogue next quarter | I4: CEO + Head of Public Affairs | J4: Maintain evidence-based, constructive tone; align with financial stability priorities | K4: 5 | L4: 5 | M4: Critical | N4: Capital strength, market stability | O4: =ROUND((B2*C2)/D2,2)
A5: ISA | B5: Insurance supervision, product approval, market conduct | C5: Product approval unit / supervision team | D5: 3 | E5: Neutral | F5: Product Q&A; market conduct documentation | G5: Technical clarification on new health rider | H5: Monthly technical session | I5: Legal + Compliance + PA | J5: Operational regulator; documentation quality and timely response matter most | K5: 5 | L5: 5 | M5: Critical | N5: Market conduct, product transparency | O5: =ROUND((B3*C3)/D3,2)
A6: IAV | B6: Industry coordination and collective advocacy | C6: Association secretariat / working groups | D6: 5 | E6: Positive | F6: Industry position on product approval circular | G6: Input to association policy paper | H6: Join working group this month | I6: Public Affairs | J6: Use industry channel for non-sensitive sector-wide policy points | K6: 3 | L6: 4 | M6: High | N6: Industry alignment | O6: =ROUND((B4*C4)/D4,2)
A7: SBV | B7: Cross-sector financial risk and bancassurance conduct | C7: Financial stability / banking supervision interface | D7: 3 | E7: Neutral | F7: Bancassurance conduct and bank distribution risk | G7: Industry dialogue via association | H7: Quarterly dialogue | I7: Government Relations Director | J7: Engage on systemic risk and customer protection; avoid narrow company-only framing | K7: 4 | L7: 3 | M7: High | N7: Bancassurance, system risk | O7: =ROUND((B5*C5)/D5,2)
A8: MIC | B8: Data, digital distribution, cybersecurity and data localization | C8: Data policy / cybersecurity consultation channel | D8: 2 | E8: Cautious | F8: Data localization and consent requirements | G8: Digital insurance compliance note | H8: Policy roundtable in two months | I8: Digital Policy Lead | J8: Relationship requires more technical credibility and early transparency | K8: 3 | L8: 4 | M8: Medium | N8: Data privacy and localization | O8: =ROUND((B6*C6)/D6,2)
A9: VCA | B9: Consumer protection and complaints oversight | C9: Consumer protection unit | D9: 3 | E9: Cautious | F9: Complaint handling transparency; mis-selling concerns | G9: Consumer education and complaint KPI note | H9: Consumer protection briefing | I9: Compliance + PA | J9: Frame as customer protection and transparency agenda | K9: 4 | L9: 4 | M9: High | N9: Consumer complaints | O9: =ROUND((B7*C7)/D7,2)
A202: Consolidation Note | B202: Merged Relationship_Intelligence into Regulator_CRM. Relationship_Intelligence sheet removed.

Sheet Knowledge_Base
A1: Regulatory Knowledge Base AI-lite
A3: Topic / Regulation | B3: Agency | C3: Summary | D3: Key Obligations | E3: Impact on Manulife | F3: Affected Departments | G3: Required Actions | H3: Status | I3: Owner | J3: Review Frequency
A4: Insurance Law / Amended Insurance Law | B4: MOF / ISA | C4: Core legal framework for insurance business, licensing, solvency, distribution and product obligations. | D4: Maintain licensed activities, solvency discipline, product compliance and market conduct standards. | E4: High impact on products, capital, reporting and distribution. | F4: Legal; Compliance; Finance; Product; Agency | G4: Maintain obligations register; update internal policies; train business owners. | H4: Active | I4: Legal + PA | J4: Quarterly
A5: Circular on Product Approval Process | B5: ISA | C5: Expected guidance tightening product filing, Q&A, disclosure and customer suitability documentation. | D5: Provide complete product dossier, customer disclosure evidence and timely responses to regulator questions. | E5: High impact on product launch timeline and internal approval process. | F5: Product; Legal; Compliance; PA | G5: Create product approval checklist and regulator Q&A tracker. | H5: Monitoring | I5: Product + PA | J5: Monthly
A6: Bancassurance Conduct Guidance | B6: SBV / MOF | C6: Guidance likely focused on sales practices, transparency and customer consent in bank distribution. | D6: Improve sales governance, disclosure and complaint handling evidence. | E6: High impact on bancassurance revenue, conduct risk and reputation. | F6: Bancassurance; Compliance; Legal; PA | G6: Prepare industry input; strengthen sales conduct monitoring. | H6: Drafting | I6: Bancassurance + Compliance | J6: Monthly
A7: Personal Data Protection / Data Localization | B7: MIC | C7: Rules on consent, data processing, cross-border transfer and storage obligations. | D7: Maintain consent records, privacy notices and controls over data sharing. | E7: Medium-high impact on digital sales and customer data operations. | F7: IT; Digital; Legal; Compliance; PA | G7: Map data flows; prepare compliance note for regulator engagement. | H7: Implementation | I7: Digital + Legal | J7: Monthly
A8: Consumer Protection Requirements | B8: VCA / ISA | C8: Rules and expectations around complaint transparency, mis-selling prevention and fair customer treatment. | D8: Maintain complaint records, remediation evidence and transparent customer communication. | E8: High reputation impact and can trigger regulatory scrutiny. | F8: Compliance; Operations; Agency; PA | G8: Build customer complaint dashboard and regulator-ready remediation pack. | H8: Effective soon | I8: Compliance + PA | J8: Monthly
A9: ESG Disclosure for Insurers | B9: MOF | C9: Emerging expectation for sustainability disclosure, responsible investment and social contribution reporting. | D9: Collect ESG data and align disclosures with group and local expectations. | E9: Medium impact; opportunity to strengthen legitimacy. | F9: Finance; Investment; Sustainability; PA | G9: Prepare baseline ESG disclosure template. | H9: Early consultation | I9: Finance + PA | J9: Quarterly

Sheet Workflow_Engine
A1: Regulatory Workflow Engine
A3: Workflow ID | B3: Workflow Name | C3: Stage | D3: Owner | E3: SLA Days | F3: Status | G3: Bottleneck | H3: Next Action | I3: Regulator / Audience | J3: Control Point
A4: WF-001 | B4: MOF official letter submission | C4: Request received | D4: Public Affairs | E4: 1 | F4: Completed | G4: None | H4: Log request and confirm scope | I4: MOF | J4: Request scope confirmation
A5: WF-001 | B5: MOF official letter submission | C5: Data collection | D5: Business Owner | E5: 3 | F5: In Progress | G5: Delayed supporting data | H5: Escalate to Product by noon | I5: MOF | J5: Data completeness check
A6: WF-001 | B6: MOF official letter submission | C6: Legal review | D6: Legal | E6: 2 | F6: Pending | G6: Awaiting draft | H6: Send version-controlled draft | I6: MOF | J6: Legal sign-off
A7: WF-001 | B7: MOF official letter submission | C7: Compliance review | D7: Compliance | E7: 2 | F7: Pending | G7: Awaiting Legal comments | H7: Review once legal draft locked | I7: MOF | J7: Compliance sign-off
A8: WF-001 | B8: MOF official letter submission | C8: Management approval | D8: CEO Office | E8: 2 | F8: Not Started | G8: Signature authority not confirmed | H8: Confirm signer and delegation matrix | I8: MOF | J8: Signature authority check
A9: WF-001 | B9: MOF official letter submission | C9: Submission | D9: Public Affairs | E9: 1 | F9: Not Started | G9: Hard copy not prepared | H9: Prepare cover letter, attachments and submission receipt | I9: MOF | J9: Submission evidence archive
A10: WF-001 | B10: MOF official letter submission | C10: Response tracking | D10: Public Affairs | E10: 5 | F10: Not Started | G10: No response yet | H10: Track receipt and expected feedback date | I10: MOF | J10: Regulator response log
A11: WF-002 | B11: ISA product approval dossier | C11: Draft dossier | D11: Product | E11: 5 | F11: Completed | G11: None | H11: Send to Legal/Compliance | I11: ISA | J11: Product dossier checklist
A12: WF-002 | B12: ISA product approval dossier | C12: Regulator Q&A | D12: Product + PA | E12: 7 | F12: In Progress | G12: Technical answers incomplete | H12: Prepare Q&A table with evidence | I12: ISA | J12: Q&A response quality check
A13: WF-003 | B13: Regional Office regulatory update | C13: Collect weekly updates | D13: Public Affairs | E13: 2 | F13: In Progress | G13: Inputs from functions late | H13: Send Friday reminder | I13: Regional Office | J13: One source of truth tracker

Sheet Executive_Brief
A1: Executive Brief Generator Data
A3: Brief Date | B3: Audience | C3: Executive Summary | D3: Top Deadline | E3: Top Risk | F3: Key Regulator Interaction | G3: Documents Not Ready | H3: Next 7-Day Priorities | I3: Prepared By
A4: 2026-06-11 | B4: CEO / EMT | C4: Regulatory operations are manageable but three items require leadership visibility: one overdue ISA follow-up, product approval Q&A, and MOF official letter readiness. | D4: Monthly solvency report due tomorrow to ISA | E4: Circular on product approval process: high business impact and consultation window within 0-3 months | F4: ISA technical session planned; MOF official letter readiness check pending | G4: 3 documents not ready or needing review | H4: Close overdue ISA follow-up; finalize MOF letter; prepare ISA product Q&A; send weekly Regional Office pack | I4: Public Affairs
A5: 2026-06-12 | B5: Regional Office | C5: No material new law detected. Key focus remains product approval process, data privacy implementation and consumer protection reporting. | D5: Regional Office weekly regulatory pack due today | E5: Bancassurance conduct guideline remains medium-high strategic risk | F5: IAV working group scheduled; MIC data privacy consultation monitored | G5: 2 documents require review | H5: Issue weekly pack; update policy radar; close legal comments on product dossier | I5: Public Affairs
A202: Consolidation Note | B202: Regional_Report_Pack and Monthly_RO_Report_Generator consolidated here. Use Audience column for CEO / Regional Office / Management.
A203: Regional Office Monthly Template | B203: Regional Office | C203: Monthly Regulatory & Public Affairs Report Pack - Template Section | Auto Summary / Suggested Content | Source Tab | Owner 1. Key regulatory developments | Summarize top 3 policy items by risk score. | Policy_Monitoring | PA 2. Regulatory submissions | Highlight overdue, due soon and submitted items. | Submission_Tracker | PA 3. Pending approvals | List product/capital/license approvals by stage. | Approval_Pipeline | PA + Business 4. Regulator interactions | Summarize meetings/calls and follow-up actions. | Regulator_Interactions | PA 5. Emerging risks | Use early warning from policy risk and relationship risk. | Policy_Monitoring + Relationship_Intelligence | PA 6. Next 30-day priorities | Actions, owners and escalation needs. | All trackers | PA Head Draft Narrative This month, the Regulatory & Public Affairs team continued to monitor key regulatory developments affecting the life insurance sector, including product approval rules, consumer protection requirements, data privacy implementation and capital adequacy discussions. Key priorities for the next 30 days are to close overdue submissions, prepare technical inputs for ISA/MOF discussions, and coordinate with Legal, Compliance and business teams to ensure timely and high-quality responses.
A204: Monthly RO Draft Generator | B204: Regional Office | C204: One-Click Monthly Regional Office Report Generator (English Draft) Field | Value | Notes | Section | Draft Text Reporting Month | June 2026 | Change monthly | 1. Executive Summary | Overall regulatory workload remains manageable. Key focus areas are product approval follow-up, consumer protection monitoring, and timely completion of periodic reports. Reports Submitted On Time | 18 | Sample data | 2. Key Regulatory Developments | No major finalized regulation this month. The team continues to monitor draft guidance on bancassurance, data privacy and consumer protection. Overdue Reports | 1 | Sample data | 3. Pending Approvals | Two approval items remain pending with the regulator: one product filing and one agent training-related submission. Follow-up actions have been assigned. Pending Approvals | 2 | Sample data | 4. Regulator Engagements | The team maintained regular working contact with ISA and MOF through technical follow-ups, document submissions and preparation for upcoming meetings. Regulator Meetings | 4 | Sample data | 5. Emerging Risks | Emerging risks include potential tightening of product approval requirements, heightened market conduct supervision and evolving data localization expectations. High Risk Policy Issues | 3 | Sample data | 6. Next Month Priorities | Priorities for next month are: close pending approval actions, prepare for upcoming regulator meetings, complete documentation quality checks, and update policy risk assessment. Internal Overdue Follow-ups | 2 | Sample data | 7. Support Needed from Regional Office | No immediate escalation is required. Regional guidance may be useful if new APAC-level interpretation is issued on data privacy or market conduct. Generated Monthly Report Draft To: Regional Office Subject: Vietnam Regulatory & Public Affairs Monthly Update - June 2026 1. Executive Summary Overall regulatory workload remains manageable. The main focus areas are product approval follow-up, consumer protection monitoring, and timely completion of regulatory reporting obligations. 2. Key Metrics - Reports submitted on time: 18 - Overdue reports: 1 - Pending approvals: 2 - Regulator meetings/interactions: 4 - High-risk policy issues: 3 - Internal overdue follow-ups: 2 3. Key Regulatory Developments No major finalized regulation was identified this month. The team continues to monitor draft guidance relating to bancassurance, data privacy, consumer protection and market conduct supervision. 4. Pending Approvals and Submissions Two approval items remain pending with the regulator: one product filing and one agent training-related submission. Responsible owners have been assigned and follow-up actions are being tracked. 5. Regulator Engagements The team maintained regular working contact with ISA and MOF through technical follow-ups, document submissions and preparation for upcoming meetings. 6. Emerging Risks Emerging risks include potential tightening of product approval requirements, increased market conduct review and evolving data localization expectations. 7. Next Month Priorities Priorities for next month are to close pending approval actions, prepare for upcoming regulator meetings, complete documentation quality checks and update the policy risk assessment.

Sheet Approval_Analytics
A1: Approval Time Analytics
A3: Regulator | B3: Approval Type | C3: No. of Cases | D3: Avg Days to Approval | E3: Median Days | F3: Longest Open Case | G3: Expected Approval Time Next Case | H3: Bottleneck | I3: Recommended Improvement
A4: ISA | B4: Product approval | C4: 12 | D4: 42 | E4: 38 | F4: APR-011 | G4: 45 | H4: Regulator Q&A and missing technical evidence | I4: Create standardized Q&A evidence pack and pre-check with Compliance
A5: MOF | B5: Capital / license | C5: 8 | D5: 55 | E5: 52 | F5: APR-005 | G5: 58 | H5: Management approval and hard-copy documentation | I5: Prepare signature matrix and document QC before internal approval
A6: IAV | B6: Industry working group input | C6: 6 | D6: 21 | E6: 18 | F6: APR-014 | G6: 24 | H6: Coordination with member companies | I6: Submit early draft positions and align through working group
A7: MIC | B7: Digital / data consultation | C7: 5 | D7: 36 | E7: 34 | F7: APR-019 | G7: 40 | H7: Technical interpretation and data mapping | I7: Maintain data-flow annex and privacy impact summary
A8: SBV / MOF | B8: Bancassurance matters | C8: 7 | D8: 48 | E8: 46 | F8: APR-018 | G8: 50 | H8: Cross-agency alignment and conduct evidence | I8: Prepare customer-protection narrative and complaint KPIs

Sheet PA_Scorecard
A1: Public Affairs Scorecard
A3: KPI Area | B3: Metric | C3: Target | D3: Current | E3: Gap | F3: RAG Status | G3: Interpretation | H3: Owner
A4: Regulatory Reporting | B4: On-time submission rate | C4: 0.98 | D4: 0.92 | E4: 0.06 | F4: Amber | G4: Operational discipline is improving but not yet target level | H4: Public Affairs
A5: Document Control | B5: Documents ready before deadline | C5: 0.95 | D5: 0.78 | E5: 0.17 | F5: Red | G5: Document quality checklist should be enforced earlier | H5: Public Affairs + Legal
A6: Regulator Relationship | B6: Average relationship strength | C6: 4 | D6: 3.33 | E6: 0.67 | F6: Amber | G6: MOF/IAV strong; MIC and ISA require further technical engagement | H6: Head of PA
A7: Policy Intelligence | B7: High-risk policy items with action plan | C7: 1 | D7: 0.9 | E7: 0.1 | F7: Amber | G7: Most risks have actions, but owners should be confirmed | H7: Public Affairs
A8: Approval Management | B8: Approvals closed within target SLA | C8: 0.9 | D8: 0.72 | E8: 0.18 | F8: Red | G8: Internal review and Q&A response are main bottlenecks | H8: Product + Legal
A9: Regional Reporting | B9: Regional reports issued on schedule | C9: 1 | D9: 1 | E9: 0 | F9: Green | G9: Reporting discipline meets expectation | H9: Public Affairs
A10: Translation Support | B10: Translation tasks on-time | C10: 0.95 | D10: 0.85 | E10: 0.1 | F10: Amber | G10: Track SLA for Regional Office documents | H10: Public Affairs

Sheet Regulatory_Obligation_Register
A1: Regulatory Obligation Register
A2: Master inventory of recurring/ad-hoc regulatory obligations for Manulife Vietnam
A4: Obligation ID | B4: Obligation | C4: Regulator | D4: Legal Basis / Source | E4: Frequency | F4: Owner Dept | G4: Submission Channel | H4: Due Rule | I4: Next Due Date | J4: Penalty / Consequence | K4: Criticality | L4: Evidence Required | M4: Control Owner | N4: Status | O4: Days to Due | P4: RAG
A5: OBL-001 | B5: Monthly solvency monitoring report | C5: ISA / MOF | D5: Insurance Law / MOF guidance | E5: Monthly | F5: Finance | G5: e-Portal + hard copy | H5: 10th working day | I5: 46193 | J5: Regulatory reminder / inspection focus | K5: Critical | L5: Signed report, calculation file, management approval | M5: Regulatory Affairs | N5: Open | O5: =I5-TODAY() | P5: =IF(O5<0,"Red",IF(O5<=7,"Amber","Green"))
A6: OBL-002 | B6: Quarterly capital adequacy report | C6: MOF | D6: Insurance supervisory reporting rules | E6: Quarterly | F6: Finance / Risk | G6: Hard copy + official letter | H6: Quarter end + 15 days | I6: 46218 | J6: High regulatory concern if delayed | K6: Critical | L6: Actuary sign-off, Finance review, Compliance review | M6: Finance | N6: Open | O6: =I6-TODAY() | P6: =IF(O6<0,"Red",IF(O6<=7,"Amber","Green"))
A7: OBL-003 | B7: New product filing / approval dossier | C7: ISA | D7: Product approval requirements | E7: Ad-hoc | F7: Product / Legal | G7: Hard copy one-stop desk | H7: Before launch | I7: 46201 | J7: Product launch delay | K7: High | L7: Product wording, pricing note, disclosure, legal opinion | M7: Product | N7: In Progress | O7: =I7-TODAY() | P7: =IF(O7<0,"Red",IF(O7<=7,"Amber","Green"))
